nohup: ignoring input
INFO:root:ðŸ”‘ Initialized SMS API session from config: PHPSESSID=jfi9fn51cr...850qte6tah
INFO:root:Bot started and polling...
INFO:httpx:HTTP Request: POST https://api.telegram.org/bot7650570527:AAG9K_XGEZ2MGcXkBc2h7cltVPQTWayhh00/getMe "HTTP/1.1 200 OK"
INFO:root:ðŸ”„ Starting background cleanup task...
INFO:root:ðŸ”„ Background OTP cleanup task started - checking every minute
INFO:httpx:HTTP Request: POST https://api.telegram.org/bot7650570527:AAG9K_XGEZ2MGcXkBc2h7cltVPQTWayhh00/deleteWebhook "HTTP/1.1 200 OK"
INFO:telegram.ext.Application:Application started
INFO:httpx:HTTP Request: POST https://api.telegram.org/bot7650570527:AAG9K_XGEZ2MGcXkBc2h7cltVPQTWayhh00/getUpdates "HTTP/1.1 409 Conflict"
ERROR:telegram.ext.Application:No error handlers are registered, logging exception.
Traceback (most recent call last):
  File "/home/ubuntu/.local/lib/python3.13/site-packages/telegram/ext/_utils/networkloop.py", line 115, in network_retry_loop
    if not await do_action():
           ^^^^^^^^^^^^^^^^^
  File "/home/ubuntu/.local/lib/python3.13/site-packages/telegram/ext/_utils/networkloop.py", line 108, in do_action
    return action_cb_task.result()
           ~~~~~~~~~~~~~~~~~~~~~^^
  File "/home/ubuntu/.local/lib/python3.13/site-packages/telegram/ext/_updater.py", line 340, in polling_action_cb
    updates = await self.bot.get_updates(
              ^^^^^^^^^^^^^^^^^^^^^^^^^^^
    ...<3 lines>...
    )
    ^
  File "/home/ubuntu/.local/lib/python3.13/site-packages/telegram/ext/_extbot.py", line 670, in get_updates
    updates = await super().get_updates(
              ^^^^^^^^^^^^^^^^^^^^^^^^^^
    ...<9 lines>...
    )
    ^
  File "/home/ubuntu/.local/lib/python3.13/site-packages/telegram/_bot.py", line 4611, in get_updates
    await self._post(
    ^^^^^^^^^^^^^^^^^
    ...<7 lines>...
    ),
    ^
  File "/home/ubuntu/.local/lib/python3.13/site-packages/telegram/_bot.py", line 698, in _post
    return await self._do_post(
           ^^^^^^^^^^^^^^^^^^^^
    ...<6 lines>...
    )
    ^
  File "/home/ubuntu/.local/lib/python3.13/site-packages/telegram/ext/_extbot.py", line 370, in _do_post
    return await super()._do_post(
           ^^^^^^^^^^^^^^^^^^^^^^^
    ...<6 lines>...
    )
    ^
  File "/home/ubuntu/.local/lib/python3.13/site-packages/telegram/_bot.py", line 727, in _do_post
    result = await request.post(
             ^^^^^^^^^^^^^^^^^^^
    ...<6 lines>...
    )
    ^
  File "/home/ubuntu/.local/lib/python3.13/site-packages/telegram/request/_baserequest.py", line 197, in post
    result = await self._request_wrapper(
             ^^^^^^^^^^^^^^^^^^^^^^^^^^^^
    ...<7 lines>...
    )
    ^
  File "/home/ubuntu/.local/lib/python3.13/site-packages/telegram/request/_baserequest.py", line 374, in _request_wrapper
    raise exception
telegram.error.Conflict: Conflict: terminated by other getUpdates request; make sure that only one bot instance is running
INFO:httpx:HTTP Request: POST https://api.telegram.org/bot7650570527:AAG9K_XGEZ2MGcXkBc2h7cltVPQTWayhh00/getUpdates "HTTP/1.1 409 Conflict"
ERROR:telegram.ext.Application:No error handlers are registered, logging exception.
Traceback (most recent call last):
  File "/home/ubuntu/.local/lib/python3.13/site-packages/telegram/ext/_utils/networkloop.py", line 115, in network_retry_loop
    if not await do_action():
           ^^^^^^^^^^^^^^^^^
  File "/home/ubuntu/.local/lib/python3.13/site-packages/telegram/ext/_utils/networkloop.py", line 108, in do_action
    return action_cb_task.result()
           ~~~~~~~~~~~~~~~~~~~~~^^
  File "/home/ubuntu/.local/lib/python3.13/site-packages/telegram/ext/_updater.py", line 340, in polling_action_cb
    updates = await self.bot.get_updates(
              ^^^^^^^^^^^^^^^^^^^^^^^^^^^
    ...<3 lines>...
    )
    ^
  File "/home/ubuntu/.local/lib/python3.13/site-packages/telegram/ext/_extbot.py", line 670, in get_updates
    updates = await super().get_updates(
              ^^^^^^^^^^^^^^^^^^^^^^^^^^
    ...<9 lines>...
    )
    ^
  File "/home/ubuntu/.local/lib/python3.13/site-packages/telegram/_bot.py", line 4611, in get_updates
    await self._post(
    ^^^^^^^^^^^^^^^^^
    ...<7 lines>...
    ),
    ^
  File "/home/ubuntu/.local/lib/python3.13/site-packages/telegram/_bot.py", line 698, in _post
    return await self._do_post(
           ^^^^^^^^^^^^^^^^^^^^
    ...<6 lines>...
    )
    ^
  File "/home/ubuntu/.local/lib/python3.13/site-packages/telegram/ext/_extbot.py", line 370, in _do_post
    return await super()._do_post(
           ^^^^^^^^^^^^^^^^^^^^^^^
    ...<6 lines>...
    )
    ^
  File "/home/ubuntu/.local/lib/python3.13/site-packages/telegram/_bot.py", line 727, in _do_post
    result = await request.post(
             ^^^^^^^^^^^^^^^^^^^
    ...<6 lines>...
    )
    ^
  File "/home/ubuntu/.local/lib/python3.13/site-packages/telegram/request/_baserequest.py", line 197, in post
    result = await self._request_wrapper(
             ^^^^^^^^^^^^^^^^^^^^^^^^^^^^
    ...<7 lines>...
    )
    ^
  File "/home/ubuntu/.local/lib/python3.13/site-packages/telegram/request/_baserequest.py", line 374, in _request_wrapper
    raise exception
telegram.error.Conflict: Conflict: terminated by other getUpdates request; make sure that only one bot instance is running
INFO:httpx:HTTP Request: POST https://api.telegram.org/bot7650570527:AAG9K_XGEZ2MGcXkBc2h7cltVPQTWayhh00/getUpdates "HTTP/1.1 409 Conflict"
ERROR:telegram.ext.Updater:Error while calling `get_updates` one more time to mark all fetched updates as read: %s. Suppressing error to ensure graceful shutdown. When polling for updates is restarted, updates may be fetched again. Please adjust timeouts via `ApplicationBuilder` or the parameter `get_updates_request` of `Bot`.
Traceback (most recent call last):
  File "/home/ubuntu/.local/lib/python3.13/site-packages/telegram/ext/_updater.py", line 399, in _get_updates_cleanup
    await self.bot.get_updates(
    ...<4 lines>...
    )
  File "/home/ubuntu/.local/lib/python3.13/site-packages/telegram/ext/_extbot.py", line 670, in get_updates
    updates = await super().get_updates(
              ^^^^^^^^^^^^^^^^^^^^^^^^^^
    ...<9 lines>...
    )
    ^
  File "/home/ubuntu/.local/lib/python3.13/site-packages/telegram/_bot.py", line 4611, in get_updates
    await self._post(
    ^^^^^^^^^^^^^^^^^
    ...<7 lines>...
    ),
    ^
  File "/home/ubuntu/.local/lib/python3.13/site-packages/telegram/_bot.py", line 698, in _post
    return await self._do_post(
           ^^^^^^^^^^^^^^^^^^^^
    ...<6 lines>...
    )
    ^
  File "/home/ubuntu/.local/lib/python3.13/site-packages/telegram/ext/_extbot.py", line 370, in _do_post
    return await super()._do_post(
           ^^^^^^^^^^^^^^^^^^^^^^^
    ...<6 lines>...
    )
    ^
  File "/home/ubuntu/.local/lib/python3.13/site-packages/telegram/_bot.py", line 727, in _do_post
    result = await request.post(
             ^^^^^^^^^^^^^^^^^^^
    ...<6 lines>...
    )
    ^
  File "/home/ubuntu/.local/lib/python3.13/site-packages/telegram/request/_baserequest.py", line 197, in post
    result = await self._request_wrapper(
             ^^^^^^^^^^^^^^^^^^^^^^^^^^^^
    ...<7 lines>...
    )
    ^
  File "/home/ubuntu/.local/lib/python3.13/site-packages/telegram/request/_baserequest.py", line 374, in _request_wrapper
    raise exception
telegram.error.Conflict: Conflict: terminated by other getUpdates request; make sure that only one bot instance is running
INFO:telegram.ext.Application:Application is stopping. This might take a moment.
INFO:telegram.ext.Application:Application.stop() complete
ERROR:asyncio:Task was destroyed but it is pending!
task: <Task pending name='Task-5' coro=<background_otp_cleanup_task() done, defined at /workspace/bot.py:2548> wait_for=<Future pending cb=[Task.task_wakeup()]>>
